<?xml version='1.0'?>

<robot name="track_robot" xmlns:xacro="http://www.ros.org/wiki/xacro">
<xacro:macro name="wheel" params="prefix x y z roll pitch yaw">
  <link name="${prefix}_wheel">
    <visual>
      <geometry>
        <cylinder radius="0.1" length="0.05"/>
      </geometry>
      <origin xyz="${x} ${y} ${z}" rpy=" ${roll} ${pitch} ${yaw}"/>
    </visual>
    <collision>
      <geometry>
        <cylinder radius="0.1" length="0.05"/>
      </geometry>
      <origin xyz="${x} ${y} ${z}" rpy=" ${roll} ${pitch} ${yaw}"/>
    </collision>
    <inertial>
     <mass value="5"/>
     <inertia ixx="0.1" ixy="0" ixz="0" iyy="0.1" iyz="0" izz="0.1"/>
    </inertial>
  </link>
  <gazebo reference="${prefix}_wheel">
    <material>Gazebo/Grey</material>
  </gazebo>
</xacro:macro>

<xacro:include filename="$(find track_robot)/urdf/track_robot.gazebo" />
  <link name="robot_footprint"></link>

  <joint name="robot_footprint_joint" type="fixed">
    <origin xyz="0 0 0" rpy="0 0 0" />
    <parent link="robot_footprint"/>
    <child link="chassis" />
  </joint>

  <link name='chassis'>
    <pose>0 0 0.1 0 0 0</pose>

    <inertial>
      <mass value="15.0"/>
      <origin xyz="0.0 0 0" rpy=" 0 0 0"/>
      <inertia
          ixx="0.1" ixy="0" ixz="0"
          iyy="0.1" iyz="0"
          izz="0.1"
      />
    </inertial>

    <collision name='collision'>
      <origin xyz="0 0 0" rpy=" 0 0 0"/> 
      <geometry>
        <box size=".4 .2 .1"/>
      </geometry>
    </collision>

    <visual name='chassis_visual'>
      <origin xyz="0 0 0" rpy=" 0 0 0"/>
      <geometry>
        <box size=".4 .2 .1"/>
      </geometry>
    </visual>


    <collision name='back_caster_collision'>
      <origin xyz="-0.15 0 -0.05" rpy=" 0 0 0"/>
      <geometry>
        <sphere radius="0.0499"/>
      </geometry>
    </collision>

    <visual name='back_caster_visual'>
      <origin xyz="-0.15 0 -0.05" rpy=" 0 0 0"/>
      <geometry>
        <sphere radius="0.05"/>
      </geometry>
    </visual>

    <collision name='front_caster_collision'>
      <origin xyz="0.15 0 -0.05" rpy=" 0 0 0"/>
      <geometry>
        <sphere radius="0.0499"/>
      </geometry>
    </collision>

    <visual name='front_caster_visual'>
      <origin xyz="0.15 0 -0.05" rpy=" 0 0 0"/>
      <geometry>
        <sphere radius="0.05"/>
      </geometry>
    </visual>

  </link>
<xacro:wheel prefix="left" x="0" y="0" z="0" roll="0" pitch="1.5707" yaw="1.5707"/>
<joint name="left_wheel_hinge" type="continuous">
  <origin xyz="0 0.125 0" rpy="0 0 0"/>
  <child link="left_wheel"/>
  <parent link="chassis"/>
  <axis xyz="0 1 0" rpy="0 0 0"/>
  <limit effort="10000" velocity="1000"/>
  <dynamics damping="1.0" friction="1.0"/>
</joint>

<xacro:wheel prefix="right" x="0" y="0" z="0" roll="0" pitch="1.5707" yaw="1.5707"/>
<joint name="right_wheel_hinge" type="continuous">
  <origin xyz="0 -0.125 0" rpy="0 0 0"/>
  <child link="right_wheel"/>
  <parent link="chassis"/>
  <axis xyz="0 1 0" rpy="0 0 0"/>
  <limit effort="10000" velocity="1000"/>
  <dynamics damping="1.0" friction="1.0"/>
</joint>

<gazebo reference="chassis">
  <material>Gazebo/SkyBlue</material>
</gazebo>

<!-- camera link -->
<link name="camera">
	<visual>
		<origin xyz="0 0 0" rpy="0 0 0"/>
		<geometry>
			<box size="0.05 0.05 0.05"/>
		</geometry>
	</visual>
	<collision>
		<origin xyz="0 0 0" rpy="0 0 0"/>
		<geometry>
			<box size="0.05 0.05 0.05"/>
		</geometry>
	</collision>
	<inertial>
		<mass value="0.1"/>
		<inertia ixx="1e-6" ixy="0" ixz="0" iyy="1e-6" iyz="0" izz="1e-6" />
	</inertial>
</link>
<joint name="camera_joint" type="fixed">
	<origin xyz="0.2 0 0" rpy="0 0 0"/>
	<parent link="chassis"/>
	<child link="camera"/>
</joint>

<!-- laser link -->
<link name="hokuyo">
	<visual>
		<origin xyz="0 0 0" rpy="0 0 0"/>
		<geometry>
			<mesh filename="package://track_robot/meshes/hokuyo.dae" size="1 1 1"/>
		</geometry>
	</visual>
	<collision>
		<origin xyz="0 0 0" rpy="0 0 0"/>
		<geometry>
			<box size="0.1 0.1 0.1"/>
		</geometry>
	</collision>
	<inertial>
		<mass value="1e-5"/>
		<inertia ixx="1e-6" ixy="0" ixz="0" iyy="1e-6" iyz="0" izz="1e-6" />
	</inertial>
</link>
<joint name="hokuyo_joint" type="fixed">
	<origin xyz="0.15 0 0.085" rpy="0 0 0"/>
	<parent link="chassis"/>
	<child link="hokuyo"/>
</joint>
</robot>
